Workbook

Sheet Stroke area raw
A1: Animal | B1: Image | C1: Ipsi striatum Area (um^2) | D1: Contra striatum Area (um^2) | E1: Stroke Area (um^2) | F1: Ipsi/Contra | G1: Use?
A2: PS46 | B2: PS46_1_8 (2) | C2: 3325070.2 | D2: 4532146.1 | E2: 595391.91 | F2: =C2/D2*100 -> 73.36635 | G2: ok
B3: PS46_1_7 | C3: 3233371.7 | D3: 4413210.9 | E3: 435696.75 | F3: =C3/D3*100 -> 73.265741 | G3: ok
B4: PS46_1_1 | C4: 4212963.9 | D4: 4721058.9 | E4: 738068.38 | F4: =C4/D4*100 -> 89.23769 | G4: good
B5: PS46_2_3 | C5: 3470603.2 | D5: 3939886.6 | E5: 601415.08 | F5: =C5/D5*100 -> 88.08891 | G5: meh
B6: PS46_2_2 | C6: 3981522.6 | D6: 3871640.6 | E6: 571020.46 | F6: =C6/D6*100 -> 102.83812 | G6: no
A7: PS47 | B7: PS47_1_8 | C7: 3780704 | D7: 4198452.6 | E7: 391022.45 | F7: =C7/D7*100 -> 90.049938 | G7: ok
B8: PS47_1_4 | C8: 3602130.6 | D8: 4152436 | E8: 328266.76 | F8: =C8/D8*100 -> 86.747407 | G8: meh
B9: PS47_1_3 | C9: 3451356.3 | D9: 4307455.3 | E9: 442831.97 | F9: =C9/D9*100 -> 80.125179 | G9: good
B10: PS47_2_6 | C10: 3461188 | D10: 4409421.8 | E10: 441280.56 | F10: =C10/D10*100 -> 78.495281 | G10: ok
B11: PS47_3_4 | C11: 3397087.1 | D11: 3697058.2 | E11: 258231.62 | F11: =C11/D11*100 -> 91.886222 | G11: meh
A12: PS48 | B12: PS48_1_8 | C12: 3765293.4 | D12: 4548579.4 | E12: 501481.39 | F12: =C12/D12*100 -> 82.779547 | G12: good
B13: PS48_1_6 | C13: 3982829.2 | D13: 4925274.5 | E13: 585355.94 | F13: =C13/D13*100 -> 80.865121 | G13: ok
B14: PS48_1_4 | C14: 3231733.2 | D14: 3769728.4 | E14: 746730.3 | F14: =C14/D14*100 -> 85.728541 | G14: good
B15: PS48_2_1 | C15: 3676099.3 | D15: 5313830.5 | E15: 767266.41 | F15: =C15/D15*100 -> 69.179837 | G15: ok
A16: PS49 | B16: PS49_1_2 | C16: 2903703.3 | D16: 3756173.4 | E16: 994735.47 | F16: =C16/D16*100 -> 77.304826 | G16: good, too anterior
B17: PS49_2_1 | C17: 3372353.5 | D17: 4915655.3 | E17: 1018006.8 | F17: =C17/D17*100 -> 68.604352 | G17: good
B18: PS49_2_4 | C18: 3317089.3 | D18: 5141560.8 | E18: 712599.87 | F18: =C18/D18*100 -> 64.515219 | G18: good
B19: PS49_2_6 | C19: 3145200.6 | D19: 5110635.8 | E19: 924585.5 | F19: =C19/D19*100 -> 61.542258 | G19: good
B20: PS49_2_8 | C20: 3440780.3 | D20: 5524695.5 | E20: 911910.48 | F20: =C20/D20*100 -> 62.279999 | G20: good
B21: PS49_2_9 | C21: 3160827.1 | D21: 4469423.3 | E21: 1066207 | F21: =C21/D21*100 -> 70.721139 | G21: good, a bit anterior
B22: PS49_2_10 | C22: 3083267.6 | D22: 4574168 | E22: 989950.79 | F22: =C22/D22*100 -> 67.406084 | G22: good, a bit anterior
A23: PS50 | B23: PS50_1_1 | C23: 2915204.2 | D23: 3967743.5 | E23: 664535.89 | F23: =C23/D23*100 -> 73.472597 | G23: good, a bit anterior
B24: PS50_1_2 | C24: 3169538.1 | D24: 4109449.7 | E24: 674350.73 | F24: =C24/D24*100 -> 77.128043 | G24: ok
B25: PS50_1_0 | C25: 2768951.1 | D25: 3547142.2 | E25: 509325.41 | F25: =C25/D25*100 -> 78.061464 | G25: good, a bit anterior
B26: PS50_2_1 | C26: 4305114.8 | D26: 5478779.8 | E26: 589536.79 | F26: =C26/D26*100 -> 78.577986 | G26: meh
A28: PS51 | B28: PS51_1_25 | C28: 3689476.8 | D28: 5844034.1 | E28: 722598.11 | F28: =C28/D28*100 -> 63.132362 | G28: good
B29: PS51_2_1 | C29: 3505246.2 | D29: 5427732.1 | E29: 651376.17 | F29: =C29/D29*100 -> 64.58031 | G29: good
B30: PS51_2_2 | C30: 2933494.8 | D30: 5223131.6 | E30: 565814.1 | F30: =C30/D30*100 -> 56.163525 | G30: ok
B31: PS51_2_3 | C31: 3517085.4 | D31: 5016377.1 | E31: 499723.9 | F31: =C31/D31*100 -> 70.112061 | G31: ok (a bit anterior)
B32: PS51_2_5 | C32: 3565465.1 | D32: 4867423.6 | E32: 258363.31 | F32: =C32/D32*100 -> 73.251588 | G32: too anterior
A33: PS54 | B33: PS54_1_16 | C33: 2347080 | D33: 4711578.5 | E33: 623285.16 | F33: =C33/D33*100 -> 49.815153 | G33: anterior
B34: PS54_1_17 | C34: 2182665.6 | D34: 5116583.3 | E34: 1070350.7 | F34: =C34/D34*100 -> 42.658655 | G34: anterior
B35: PS54_1_18 | C35: 2010191.8 | D35: 5419348.3 | E35: 1506636.7 | F35: =C35/D35*100 -> 37.09287 | G35: meh (anterior)
B36: PS54_1_19 | C36: 1192002.4 | D36: 5362829.8 | E36: 1897998.4 | F36: =C36/D36*100 -> 22.227117 | G36: good
B37: PS54_1_20 | C37: 861282.56 | D37: 5093956.9 | E37: 2463266.2 | F37: =C37/D37*100 -> 16.907928 | G37: good
B38: PS54_2_1 | C38: 1145361 | D38: 4500530.1 | E38: 1740091 | F38: =C38/D38*100 -> 25.44947 | G38: good
B39: PS54_2_5 | C39: 855513.98 | D39: 3970740.1 | E39: 1576541.5 | F39: =C39/D39*100 -> 21.545454 | G39: good
B40: PS54_2_8 | C40: 836109.6 | D40: 3328609.8 | E40: 1189344.4 | F40: =C40/D40*100 -> 25.118883 | G40: good
A41: PS55 | B41: PS55_1_10 | C41: 838978.75 | D41: 4048727.1 | E41: 1918664.8 | F41: =C41/D41*100 -> 20.722037 | G41: ok
...

Sheet Stroke area
B1: Ipsi/Contra % area | C1: Section
A2: PS46 | B2: 82.31 | C2: PS46_1_8 | E2: PS46 | F2: 73.36635 | G2: 73.27 | H2: 89.24 | I2: 88.09
A3: PS46 | B3: 73.27 | C3: PS46_1_7 | E3: PS47 | F3: 90.049938 | G3: 86.747407 | H3: 80.125179 | I3: 78.495281 | J3: 91.886222
A4: PS46 | B4: 89.24 | C4: PS46_1_1 | E4: PS48 | F4: 82.779547 | G4: 80.865121 | H4: 85.728541 | I4: 69.179837
A5: PS46 | B5: 88.09 | C5: PS46_2_3 | E5: PS49 | F5: 68.604352 | G5: 64.515219 | H5: 61.542258 | I5: 62.279999 | J5: 70.721139 | K5: 67.406084
A6: PS47 | B6: 90.049938 | C6: PS47_1_8 | E6: PS50 | F6: 73.472597 | G6: 77.128043 | H6: 78.061464 | I6: 78.577986
A7: PS47 | B7: 86.747407 | C7: PS47_1_4 | E7: PS51 | F7: 63.132362 | G7: 64.58031 | H7: 56.163525 | I7: 70.112061
A8: PS47 | B8: 80.125179 | C8: PS47_1_3 | E8: PS54 | F8: 37.09287 | G8: 22.227117 | H8: 16.907928 | I8: 25.44947 | J8: 21.545454 | K8: 25.118883
A9: PS47 | B9: 78.495281 | C9: PS47_2_6 | E9: PS55 | F9: 20.722037 | G9: 20.353676 | H9: 15.851347 | I9: 16.956777 | J9: 18.14088 | K9: 26.101862 | L9: 18.16993 | M9: 18.798535
A10: PS47 | B10: 91.886222 | C10: PS47_3_4
A11: PS48 | B11: 82.779547 | C11: PS48_1_8
A12: PS48 | B12: 80.865121 | C12: PS48_1_6
A13: PS48 | B13: 85.728541 | C13: PS48_1_4
A14: PS48 | B14: 69.179837 | C14: PS48_2_1
A15: PS51 | B15: 63.132362 | C15: PS51_1_25
A16: PS51 | B16: 64.58031 | C16: PS51_2_1
A17: PS51 | B17: 56.163525 | C17: PS51_2_2
A18: PS51 | B18: 70.112061 | C18: PS51_2_3
A19: PS54 | B19: 37.09287 | C19: PS54_1_18
A20: PS54 | B20: 22.227117 | C20: PS54_1_19
A21: PS54 | B21: 16.907928 | C21: PS54_1_20
... A27: PS55 | B27: 15.851347 | C27: PS55_1_14
A28: PS55 | B28: ='Stroke area raw'!C45/'Stroke area raw'!D45*100 -> 16.956777 | C28: PS55_1_16
A29: PS55 | B29: ='Stroke area raw'!C46/'Stroke area raw'!D46*100 -> 18.14088 | C29: PS55_1_17
A30: PS55 | B30: ='Stroke area raw'!C47/'Stroke area raw'!D47*100 -> 26.101862 | C30: PS55_1_18
A31: PS55 | B31: ='Stroke area raw'!C48/'Stroke area raw'!D48*100 -> 18.16993 | C31: PS55_1_19
A32: PS55 | B32: ='Stroke area raw'!C49/'Stroke area raw'!D49*100 -> 18.798535 | C32: PS55_1_20

Sheet Weights
A1: Last pre-stroke session - PS51 2025-04-29; PS54-55 2025-04-30; PS46-48 2025-03-13; PS49: 2025-03-17; PS50: 2025-03-23
A2: Weight (g) | B2: PS46 | C2: PS47 | D2: PS48 | E2: PS49 | F2: PS50 | I2: PS51 | J2: PS54 | K2: PS55
A3: 45714 | B3: 16.1 | C3: 17.6 | D3: 16.4 | H3: 45763 | I3: 20.5 | J3: 20.3 | K3: 20.4
A4: 45715 | B4: 16.4 | C4: 17.8 | D4: 16 | E4: 19.1 | F4: 18.1 | H4: 45764 | I4: 20.8 | J4: 20.3 | K4: 20.4
A5: 45716 | B5: 16 | C5: 17.4 | F5: 17.7 | H5: 45765 | I5: 20.8 | J5: 20.6 | K5: 20.5
A6: 45717 | C6: 17.1 | E6: 18.3 | F6: 17.4 | H6: 45766
A7: 45718 | B7: 16.3 | E7: 18.4 | F7: 17.4 | H7: 45767
A8: 45719 | B8: 16.2 | C8: 16.8 | D8: 16.4 | F8: 17.3 | H8: 45768 | I8: 22.2 | J8: 22.6 | K8: 21.9
A9: 45720 | B9: 16.4 | D9: 16.4 | E9: 18.3 | F9: 17.3 | H9: 45769 | I9: 21.3 | J9: 21.8 | K9: 21.1
A10: 45721 | B10: 16.5 | C10: 17.2 | D10: 16.9 | E10: 18.3 | F10: 17.3 | H10: 45770 | I10: 20.9 | J10: 20.9 | K10: 21.1
A11: 45722 | B11: 17.2 | C11: 17.7 | D11: 16.7 | E11: 18.4 | F11: 17.3 | H11: 45771 | I11: 20.8 | J11: 21.8 | K11: 21.3
A12: 45723 | B12: 17.1 | C12: 17.4 | D12: 16.6 | E12: 18 | F12: 17.5 | H12: 45772 | I12: 20.8 | J12: 20.9 | K12: 21.1
A13: 45724 | B13: 17.4 | C13: 17.6 | D13: 17.4 | E13: 18 | F13: 17.8 | H13: 45773 | I13: 20.8 | J13: 20.8 | K13: 20.3
A14: 45725 | B14: 17.4 | C14: 17.7 | D14: 16.9 | E14: 18.1 | F14: 18.2 | H14: 45774 | I14: 21.1 | J14: 20.5 | K14: 20.6
A15: 45726 | B15: 17.4 | C15: 17.3 | D15: 16.9 | E15: 18.8 | F15: 18 | H15: 45775 | I15: 21 | J15: 20.4 | K15: 20.6
A16: 45727 | B16: 17.6 | C16: 17.4 | D16: 17.1 | E16: 18.4 | F16: 18 | H16: 45776 | I16: 20.1 | J16: 20.2 | K16: 20.8
A17: 45728 | B17: 17.5 | C17: 17.4 | D17: 17 | E17: 18.3 | F17: 18.1 | H17: 45777 | I17: 20.2 | J17: 19.8 | K17: 21
A18: 45729 | B18: 17.5 | C18: 17.2 | D18: 17.4 | E18: 18 | F18: 17.9 | H18: 45778 | I18: 19.3 | J18: 20.1 | K18: 20.2
A19: 45730 | B19: 17.3 | C19: 17.3 | D19: 17.2 | E19: 17.4 | F19: 17.5 | H19: 45779 | I19: 19.8 | J19: 19.2 | K19: 20.1
A20: 45731 | B20: 16.9 | C20: 16.8 | D20: 17.2 | E20: 18.2 | F20: 18.1 | H20: 45780 | I20: 20.2 | J20: 19.1 | K20: 20.1
A21: 45732 | B21: 17 | C21: 16.8 | D21: 17.1 | E21: 18.2 | F21: 18 | H21: 45781 | I21: 20.7 | J21: 19 | K21: 19.4
A22: 45733 | B22: 16.3 | C22: 16.5 | D22: 17.2 | E22: 18.2 | F22: 18 | H22: 45782 | I22: 20 | J22: 19.3 | K22: 19.2
A23: 45734 | B23: 16.1 | C23: 17.1 | D23: 17 | E23: 18.3 | H23: 45783 | I23: 20.6 | J23: 18.7 | K23: 18.5
A24: 45735 | B24: 16.4 | C24: 16.8 | D24: 16.6 | E24: 17.9 | F24: 18.1 | H24: 45784 | I24: 22.1 | J24: 19.9 | K24: 17.8
A25: 45736 | B25: 16.8 | C25: 17.2 | D25: 16.9 | E25: 18.2 | F25: 18.15 | H25: 45785 | I25: 22 | J25: 19.4 | K25: 18.2
A26: 45737 | B26: 16.8 | C26: 17.4 | D26: 17.2 | E26: 18.3 | F26: 18.2 | H26: 45786 | I26: 21 | J26: 20.5 | K26: 19.7
A27: 45738 | B27: 16.7 | C27: 17.7 | D27: 17.1 | E27: 18.2 | F27: 18.1 | H27: 45787
A28: 45739 | B28: 16.7 | C28: 17.3 | D28: 17 | E28: 18.2 | F28: 18 | H28: 45788 | I28: 21.2 | J28: 19.6 | K28: 19.3
A29: 45740 | B29: 17.4 | C29: 18.4 | D29: 17.8 | E29: 18.4 | F29: 17.95 | H29: 45789 | I29: 21.3 | J29: 19.7 | K29: 19.5
A30: 45741 | B30: 17.1 | C30: 18.1 | D30: 17.3 | E30: 18.4 | F30: 17.3 | H30: 45790
A31: 45742 | B31: 16.8 | C31: 17.9 | D31: 17.4 | E31: 18.5 | F31: 16.7 | H31: 45791 | I31: 21.1 | J31: 19.8 | K31: 19.2
A32: 45743 | B32: 17.2 | C32: 18.2 | D32: 17.5 | F32: 17.4 | H32: 45792 | I32: 20.9 | J32: 20.4 | K32: 21.5
A33: 45744 | E33: 19.1 | F33: 17.3 | H33: 45793 | I33: 20.9 | J33: 19.4 | K33: 20.2
A34: 45745 | E34: 18.8 | F34: 17.45 | H34: 45794
A35: 45746 | E35: 18.6 | F35: 17.8 | H35: 45795 | I35: 20.9 | J35: 20.9 | K35: 21.2
A36: 45747 | E36: 18.75 | F36: 17.9 | H36: 45796 | I36: 21 | J36: 20.4 | K36: 20.7
A37: 45748 | F37: 17.8 | H37: 45797
A38: 45749 | F38: 18 | H38: 45798 | I38: 21 | J38: 19.5 | K38: 20
A39: 45750 | F39: 17.8 | H39: 45799 | I39: 21.2 | J39: 20.3 | K39: 19.9
A40: 45751 | F40: 18.3 | H40: 45800 | I40: 21.4 | J40: 19.9 | K40: 20
...
